[2025-05-25T09:15:25.614+0000] {local_task_job_runner.py:120} INFO - ::group::Pre task execution logs
[2025-05-25T09:15:25.635+0000] {taskinstance.py:2076} INFO - Dependencies all met for dep_context=non-requeueable deps ti=<TaskInstance: weather_etl_pipeline.load_weather_data manual__2025-05-25T09:15:12.202220+00:00 [queued]>
[2025-05-25T09:15:25.657+0000] {taskinstance.py:2076} INFO - Dependencies all met for dep_context=requeueable deps ti=<TaskInstance: weather_etl_pipeline.load_weather_data manual__2025-05-25T09:15:12.202220+00:00 [queued]>
[2025-05-25T09:15:25.659+0000] {taskinstance.py:2306} INFO - Starting attempt 1 of 1
[2025-05-25T09:15:25.719+0000] {taskinstance.py:2330} INFO - Executing <Task(PythonOperator): load_weather_data> on 2025-05-25 09:15:12.202220+00:00
[2025-05-25T09:15:25.726+0000] {standard_task_runner.py:63} INFO - Started process 1235 to run task
[2025-05-25T09:15:25.735+0000] {standard_task_runner.py:90} INFO - Running: ['airflow', 'tasks', 'run', 'weather_etl_pipeline', 'load_weather_data', 'manual__2025-05-25T09:15:12.202220+00:00', '--job-id', '34', '--raw', '--subdir', 'DAGS_FOLDER/etl_weather.py', '--cfg-path', '/tmp/tmpyev0hghx']
[2025-05-25T09:15:25.737+0000] {standard_task_runner.py:91} INFO - Job 34: Subtask load_weather_data
[2025-05-25T09:15:25.827+0000] {task_command.py:426} INFO - Running <TaskInstance: weather_etl_pipeline.load_weather_data manual__2025-05-25T09:15:12.202220+00:00 [running]> on host fa09eeb0c661
[2025-05-25T09:15:25.986+0000] {taskinstance.py:2648} INFO - Exporting env vars: AIRFLOW_CTX_DAG_OWNER='airflow' AIRFLOW_CTX_DAG_ID='weather_etl_pipeline' AIRFLOW_CTX_TASK_ID='load_weather_data' AIRFLOW_CTX_EXECUTION_DATE='2025-05-25T09:15:12.202220+00:00' AIRFLOW_CTX_TRY_NUMBER='1' AIRFLOW_CTX_DAG_RUN_ID='manual__2025-05-25T09:15:12.202220+00:00'
[2025-05-25T09:15:25.987+0000] {taskinstance.py:430} INFO - ::endgroup::
[2025-05-25T09:15:26.012+0000] {taskinstance.py:441} INFO - ::group::Post task execution logs
[2025-05-25T09:15:26.013+0000] {taskinstance.py:2905} ERROR - Task failed with exception
Traceback (most recent call last):
  File "/home/airflow/.local/lib/python3.10/site-packages/airflow/models/taskinstance.py", line 465, in _execute_task
    result = _execute_callable(context=context, **execute_callable_kwargs)
  File "/home/airflow/.local/lib/python3.10/site-packages/airflow/models/taskinstance.py", line 432, in _execute_callable
    return execute_callable(context=context, **execute_callable_kwargs)
  File "/home/airflow/.local/lib/python3.10/site-packages/airflow/models/baseoperator.py", line 400, in wrapper
    return func(self, *args, **kwargs)
  File "/home/airflow/.local/lib/python3.10/site-packages/airflow/operators/python.py", line 235, in execute
    return_value = self.execute_callable()
  File "/home/airflow/.local/lib/python3.10/site-packages/airflow/operators/python.py", line 252, in execute_callable
    return self.python_callable(*self.op_args, **self.op_kwargs)
  File "/opt/airflow/dags/etl_weather.py", line 68, in load_weather_data
    conn = my_hook.get_conn()
NameError: name 'my_hook' is not defined
[2025-05-25T09:15:26.028+0000] {taskinstance.py:1206} INFO - Marking task as FAILED. dag_id=weather_etl_pipeline, task_id=load_weather_data, run_id=manual__2025-05-25T09:15:12.202220+00:00, execution_date=20250525T091512, start_date=20250525T091525, end_date=20250525T091526
[2025-05-25T09:15:26.057+0000] {standard_task_runner.py:110} ERROR - Failed to execute job 34 for task load_weather_data (name 'my_hook' is not defined; 1235)
[2025-05-25T09:15:26.066+0000] {local_task_job_runner.py:240} INFO - Task exited with return code 1
[2025-05-25T09:15:26.086+0000] {taskinstance.py:3498} INFO - 0 downstream tasks scheduled from follow-on schedule check
[2025-05-25T09:15:26.087+0000] {local_task_job_runner.py:222} INFO - ::endgroup::
