[2025-05-24T20:14:09.574+0000] {local_task_job_runner.py:120} INFO - ::group::Pre task execution logs
[2025-05-24T20:14:09.610+0000] {taskinstance.py:2076} INFO - Dependencies all met for dep_context=non-requeueable deps ti=<TaskInstance: mysql_query_dag.query_mysql_data manual__2025-05-24T20:14:05.206310+00:00 [queued]>
[2025-05-24T20:14:09.623+0000] {taskinstance.py:2076} INFO - Dependencies all met for dep_context=requeueable deps ti=<TaskInstance: mysql_query_dag.query_mysql_data manual__2025-05-24T20:14:05.206310+00:00 [queued]>
[2025-05-24T20:14:09.623+0000] {taskinstance.py:2306} INFO - Starting attempt 1 of 1
[2025-05-24T20:14:09.659+0000] {taskinstance.py:2330} INFO - Executing <Task(PythonOperator): query_mysql_data> on 2025-05-24 20:14:05.206310+00:00
[2025-05-24T20:14:09.667+0000] {standard_task_runner.py:63} INFO - Started process 356 to run task
[2025-05-24T20:14:09.680+0000] {standard_task_runner.py:90} INFO - Running: ['airflow', 'tasks', 'run', 'mysql_query_dag', 'query_mysql_data', 'manual__2025-05-24T20:14:05.206310+00:00', '--job-id', '19', '--raw', '--subdir', 'DAGS_FOLDER/code_2.py', '--cfg-path', '/tmp/tmp_qvnr7la']
[2025-05-24T20:14:09.688+0000] {standard_task_runner.py:91} INFO - Job 19: Subtask query_mysql_data
[2025-05-24T20:14:09.826+0000] {task_command.py:426} INFO - Running <TaskInstance: mysql_query_dag.query_mysql_data manual__2025-05-24T20:14:05.206310+00:00 [running]> on host fa09eeb0c661
[2025-05-24T20:14:09.988+0000] {taskinstance.py:2648} INFO - Exporting env vars: AIRFLOW_CTX_DAG_OWNER='airflow' AIRFLOW_CTX_DAG_ID='mysql_query_dag' AIRFLOW_CTX_TASK_ID='query_mysql_data' AIRFLOW_CTX_EXECUTION_DATE='2025-05-24T20:14:05.206310+00:00' AIRFLOW_CTX_TRY_NUMBER='1' AIRFLOW_CTX_DAG_RUN_ID='manual__2025-05-24T20:14:05.206310+00:00'
[2025-05-24T20:14:09.989+0000] {taskinstance.py:430} INFO - ::endgroup::
[2025-05-24T20:14:10.030+0000] {base.py:84} INFO - Using connection ID 'my_mysql_conn' for task execution.
[2025-05-24T20:14:10.105+0000] {taskinstance.py:441} INFO - ::group::Post task execution logs
[2025-05-24T20:14:10.106+0000] {taskinstance.py:2905} ERROR - Task failed with exception
Traceback (most recent call last):
  File "/home/airflow/.local/lib/python3.10/site-packages/airflow/models/taskinstance.py", line 465, in _execute_task
    result = _execute_callable(context=context, **execute_callable_kwargs)
  File "/home/airflow/.local/lib/python3.10/site-packages/airflow/models/taskinstance.py", line 432, in _execute_callable
    return execute_callable(context=context, **execute_callable_kwargs)
  File "/home/airflow/.local/lib/python3.10/site-packages/airflow/models/baseoperator.py", line 400, in wrapper
    return func(self, *args, **kwargs)
  File "/home/airflow/.local/lib/python3.10/site-packages/airflow/operators/python.py", line 235, in execute
    return_value = self.execute_callable()
  File "/home/airflow/.local/lib/python3.10/site-packages/airflow/operators/python.py", line 252, in execute_callable
    return self.python_callable(*self.op_args, **self.op_kwargs)
  File "/opt/airflow/dags/code_2.py", line 8, in query_mysql
    conn = hook.get_conn()
  File "/home/airflow/.local/lib/python3.10/site-packages/airflow/providers/mysql/hooks/mysql.py", line 195, in get_conn
    return MySQLdb.connect(**conn_config)
  File "/home/airflow/.local/lib/python3.10/site-packages/MySQLdb/__init__.py", line 121, in Connect
    return Connection(*args, **kwargs)
  File "/home/airflow/.local/lib/python3.10/site-packages/MySQLdb/connections.py", line 195, in __init__
    super().__init__(*args, **kwargs2)
MySQLdb.OperationalError: (1045, "Access denied for user 'root'@'localhost' (using password: NO)")
[2025-05-24T20:14:10.123+0000] {taskinstance.py:1206} INFO - Marking task as FAILED. dag_id=mysql_query_dag, task_id=query_mysql_data, run_id=manual__2025-05-24T20:14:05.206310+00:00, execution_date=20250524T201405, start_date=20250524T201409, end_date=20250524T201410
[2025-05-24T20:14:10.159+0000] {standard_task_runner.py:110} ERROR - Failed to execute job 19 for task query_mysql_data ((1045, "Access denied for user 'root'@'localhost' (using password: NO)"); 356)
[2025-05-24T20:14:10.172+0000] {local_task_job_runner.py:240} INFO - Task exited with return code 1
[2025-05-24T20:14:10.192+0000] {taskinstance.py:3498} INFO - 0 downstream tasks scheduled from follow-on schedule check
[2025-05-24T20:14:10.193+0000] {local_task_job_runner.py:222} INFO - ::endgroup::
