[2025-05-25T09:16:10.519+0000] {local_task_job_runner.py:120} INFO - ::group::Pre task execution logs
[2025-05-25T09:16:10.539+0000] {taskinstance.py:2076} INFO - Dependencies all met for dep_context=non-requeueable deps ti=<TaskInstance: weather_etl_pipeline.load_weather_data manual__2025-05-25T09:15:56.292641+00:00 [queued]>
[2025-05-25T09:16:10.550+0000] {taskinstance.py:2076} INFO - Dependencies all met for dep_context=requeueable deps ti=<TaskInstance: weather_etl_pipeline.load_weather_data manual__2025-05-25T09:15:56.292641+00:00 [queued]>
[2025-05-25T09:16:10.551+0000] {taskinstance.py:2306} INFO - Starting attempt 1 of 1
[2025-05-25T09:16:10.580+0000] {taskinstance.py:2330} INFO - Executing <Task(PythonOperator): load_weather_data> on 2025-05-25 09:15:56.292641+00:00
[2025-05-25T09:16:10.588+0000] {standard_task_runner.py:63} INFO - Started process 1267 to run task
[2025-05-25T09:16:10.590+0000] {standard_task_runner.py:90} INFO - Running: ['airflow', 'tasks', 'run', 'weather_etl_pipeline', 'load_weather_data', 'manual__2025-05-25T09:15:56.292641+00:00', '--job-id', '37', '--raw', '--subdir', 'DAGS_FOLDER/etl_weather.py', '--cfg-path', '/tmp/tmpm9dlhl9b']
[2025-05-25T09:16:10.592+0000] {standard_task_runner.py:91} INFO - Job 37: Subtask load_weather_data
[2025-05-25T09:16:10.659+0000] {task_command.py:426} INFO - Running <TaskInstance: weather_etl_pipeline.load_weather_data manual__2025-05-25T09:15:56.292641+00:00 [running]> on host fa09eeb0c661
[2025-05-25T09:16:10.780+0000] {taskinstance.py:2648} INFO - Exporting env vars: AIRFLOW_CTX_DAG_OWNER='airflow' AIRFLOW_CTX_DAG_ID='weather_etl_pipeline' AIRFLOW_CTX_TASK_ID='load_weather_data' AIRFLOW_CTX_EXECUTION_DATE='2025-05-25T09:15:56.292641+00:00' AIRFLOW_CTX_TRY_NUMBER='1' AIRFLOW_CTX_DAG_RUN_ID='manual__2025-05-25T09:15:56.292641+00:00'
[2025-05-25T09:16:10.781+0000] {taskinstance.py:430} INFO - ::endgroup::
[2025-05-25T09:16:10.814+0000] {base.py:84} INFO - Using connection ID 'mysql_default' for task execution.
[2025-05-25T09:16:18.404+0000] {taskinstance.py:441} INFO - ::group::Post task execution logs
[2025-05-25T09:16:18.404+0000] {taskinstance.py:2905} ERROR - Task failed with exception
Traceback (most recent call last):
  File "/home/airflow/.local/lib/python3.10/site-packages/airflow/models/taskinstance.py", line 465, in _execute_task
    result = _execute_callable(context=context, **execute_callable_kwargs)
  File "/home/airflow/.local/lib/python3.10/site-packages/airflow/models/taskinstance.py", line 432, in _execute_callable
    return execute_callable(context=context, **execute_callable_kwargs)
  File "/home/airflow/.local/lib/python3.10/site-packages/airflow/models/baseoperator.py", line 400, in wrapper
    return func(self, *args, **kwargs)
  File "/home/airflow/.local/lib/python3.10/site-packages/airflow/operators/python.py", line 235, in execute
    return_value = self.execute_callable()
  File "/home/airflow/.local/lib/python3.10/site-packages/airflow/operators/python.py", line 252, in execute_callable
    return self.python_callable(*self.op_args, **self.op_kwargs)
  File "/opt/airflow/dags/etl_weather.py", line 68, in load_weather_data
    conn = mysql_hook.get_conn()
  File "/home/airflow/.local/lib/python3.10/site-packages/airflow/providers/mysql/hooks/mysql.py", line 195, in get_conn
    return MySQLdb.connect(**conn_config)
  File "/home/airflow/.local/lib/python3.10/site-packages/MySQLdb/__init__.py", line 121, in Connect
    return Connection(*args, **kwargs)
  File "/home/airflow/.local/lib/python3.10/site-packages/MySQLdb/connections.py", line 195, in __init__
    super().__init__(*args, **kwargs2)
MySQLdb.OperationalError: (2005, "Unknown server host 'mysql' (-2)")
[2025-05-25T09:16:18.426+0000] {taskinstance.py:1206} INFO - Marking task as FAILED. dag_id=weather_etl_pipeline, task_id=load_weather_data, run_id=manual__2025-05-25T09:15:56.292641+00:00, execution_date=20250525T091556, start_date=20250525T091610, end_date=20250525T091618
[2025-05-25T09:16:18.451+0000] {standard_task_runner.py:110} ERROR - Failed to execute job 37 for task load_weather_data ((2005, "Unknown server host 'mysql' (-2)"); 1267)
[2025-05-25T09:16:18.483+0000] {local_task_job_runner.py:240} INFO - Task exited with return code 1
[2025-05-25T09:16:18.505+0000] {taskinstance.py:3498} INFO - 0 downstream tasks scheduled from follow-on schedule check
[2025-05-25T09:16:18.507+0000] {local_task_job_runner.py:222} INFO - ::endgroup::
