[2025-05-24T19:04:24.338+0000] {local_task_job_runner.py:120} INFO - ::group::Pre task execution logs
[2025-05-24T19:04:24.365+0000] {taskinstance.py:2076} INFO - Dependencies all met for dep_context=non-requeueable deps ti=<TaskInstance: welcome_dag.print_date_format scheduled__2025-05-23T00:04:00+00:00 [queued]>
[2025-05-24T19:04:24.374+0000] {taskinstance.py:2076} INFO - Dependencies all met for dep_context=requeueable deps ti=<TaskInstance: welcome_dag.print_date_format scheduled__2025-05-23T00:04:00+00:00 [queued]>
[2025-05-24T19:04:24.374+0000] {taskinstance.py:2306} INFO - Starting attempt 1 of 1
[2025-05-24T19:04:24.395+0000] {taskinstance.py:2330} INFO - Executing <Task(PythonOperator): print_date_format> on 2025-05-23 00:04:00+00:00
[2025-05-24T19:04:24.398+0000] {standard_task_runner.py:63} INFO - Started process 216 to run task
[2025-05-24T19:04:24.400+0000] {standard_task_runner.py:90} INFO - Running: ['airflow', 'tasks', 'run', 'welcome_dag', 'print_date_format', 'scheduled__2025-05-23T00:04:00+00:00', '--job-id', '14', '--raw', '--subdir', 'DAGS_FOLDER/welcome.py', '--cfg-path', '/tmp/tmpj7fvnigc']
[2025-05-24T19:04:24.402+0000] {standard_task_runner.py:91} INFO - Job 14: Subtask print_date_format
[2025-05-24T19:04:24.457+0000] {task_command.py:426} INFO - Running <TaskInstance: welcome_dag.print_date_format scheduled__2025-05-23T00:04:00+00:00 [running]> on host fa09eeb0c661
[2025-05-24T19:04:24.546+0000] {taskinstance.py:2648} INFO - Exporting env vars: AIRFLOW_CTX_DAG_OWNER='airflow' AIRFLOW_CTX_DAG_ID='welcome_dag' AIRFLOW_CTX_TASK_ID='print_date_format' AIRFLOW_CTX_EXECUTION_DATE='2025-05-23T00:04:00+00:00' AIRFLOW_CTX_TRY_NUMBER='1' AIRFLOW_CTX_DAG_RUN_ID='scheduled__2025-05-23T00:04:00+00:00'
[2025-05-24T19:04:24.547+0000] {taskinstance.py:430} INFO - ::endgroup::
[2025-05-24T19:04:24.557+0000] {taskinstance.py:441} INFO - ::group::Post task execution logs
[2025-05-24T19:04:24.557+0000] {taskinstance.py:2905} ERROR - Task failed with exception
Traceback (most recent call last):
  File "/home/airflow/.local/lib/python3.10/site-packages/airflow/models/taskinstance.py", line 465, in _execute_task
    result = _execute_callable(context=context, **execute_callable_kwargs)
  File "/home/airflow/.local/lib/python3.10/site-packages/airflow/models/taskinstance.py", line 432, in _execute_callable
    return execute_callable(context=context, **execute_callable_kwargs)
  File "/home/airflow/.local/lib/python3.10/site-packages/airflow/models/baseoperator.py", line 400, in wrapper
    return func(self, *args, **kwargs)
  File "/home/airflow/.local/lib/python3.10/site-packages/airflow/operators/python.py", line 235, in execute
    return_value = self.execute_callable()
  File "/home/airflow/.local/lib/python3.10/site-packages/airflow/operators/python.py", line 252, in execute_callable
    return self.python_callable(*self.op_args, **self.op_kwargs)
  File "/opt/airflow/dags/welcome.py", line 29, in print_date_format
    print("Printing the date format",name);
NameError: name 'name' is not defined
[2025-05-24T19:04:24.571+0000] {taskinstance.py:1206} INFO - Marking task as FAILED. dag_id=welcome_dag, task_id=print_date_format, run_id=scheduled__2025-05-23T00:04:00+00:00, execution_date=20250523T000400, start_date=20250524T190424, end_date=20250524T190424
[2025-05-24T19:04:24.594+0000] {standard_task_runner.py:110} ERROR - Failed to execute job 14 for task print_date_format (name 'name' is not defined; 216)
[2025-05-24T19:04:24.613+0000] {local_task_job_runner.py:240} INFO - Task exited with return code 1
[2025-05-24T19:04:24.631+0000] {taskinstance.py:3498} INFO - 0 downstream tasks scheduled from follow-on schedule check
[2025-05-24T19:04:24.632+0000] {local_task_job_runner.py:222} INFO - ::endgroup::
